Traceback (most recent call last):
  File "library/python/runtime_py3/test/traceback/crash.py", line 44, in main
  File "library/python/runtime_py3/test/traceback/crash.py", line 12, in one
  File "library/python/runtime_py3/test/traceback/mod/__init__.py", line 3, in modfunc
  File "library/python/runtime_py3/test/traceback/crash.py", line 16, in two
  File "library/python/runtime_py3/test/traceback/crash.py", line 20, in three
RuntimeError: Kaboom! I'm dead: 42
